Workbook

Sheet README
A1: Specialist AHT Summary Report — Sample Data
A3: This is a sanitized sample recreated for portfolio purposes.
A4: Structure, headcount, and formula logic (VLOOKUP / IF) reflect an actual weekly AHT tracker I owned.
A5: All names, TL handles, product taxonomy, and metric values are fictional / randomized.

Sheet WFM Q4 Target
A1: Quarter | B1: product_level1_name | C1: product_level2_name | D1: delivery_country | E1: Audit Stage | F1: Audit Stage (for mapping) | G1: Template/Ticket_type | H1: Region | I1: AHT Targets(mins) | J1: Helper | K1: AHT Targets(secs)
A2: Q4'24 | E2: Appeals | F2: Appeals | G2: T0 - Ad Group Rejection Proactive Appeal (Smart Assign) | I2: 4.426 | J2: =TRIM(E2) & TRIM(C2) & TRIM(D2) -> Appeals | K2: =IFERROR(I2*60,"") -> 265.56
A3: Q4'24 | E3: Appeals | F3: Appeals | G3: T0 - Ad Group Rejection Proactive Appeal Followup (Smart Assign) | I3: 4.4088 | J3: =TRIM(E3) & TRIM(C3) & TRIM(D3) -> Appeals | K3: =IFERROR(I3*60,"") -> 264.528
A4: Q4'24 | E4: Appeals | F4: Appeals | G4: Premium - Ad Group Rejection Proactive Appeal (Smart Assign) | I4: 6.1313 | J4: =TRIM(E4) & TRIM(C4) & TRIM(D4) -> Appeals | K4: =IFERROR(I4*60,"") -> 367.878
A5: Q4'24 | E5: Appeals | F5: Appeals | G5: Premium - Account Suspension Proactive Appeal (Smart Assign) | I5: 5.8448 | J5: =TRIM(E5) & TRIM(C5) & TRIM(D5) -> Appeals | K5: =IFERROR(I5*60,"") -> 350.688
A6: Q4'24 | E6: Appeals | F6: Appeals | G6: R&F Disapproval Inquiry (Smart Assign) | I6: 7.3193 | J6: =TRIM(E6) & TRIM(C6) & TRIM(D6) -> Appeals | K6: =IFERROR(I6*60,"") -> 439.158
A7: Q4'24 | E7: Appeals | F7: Appeals | G7: Account Suspension Appeal (Smart Assign) | I7: 5.4015 | J7: =TRIM(E7) & TRIM(C7) & TRIM(D7) -> Appeals | K7: =IFERROR(I7*60,"") -> 324.09
A8: Q4'24 | E8: Appeals | F8: Appeals | G8: Spark Ad Group Appeal (Smart Assign) | I8: 4.6096 | J8: =TRIM(E8) & TRIM(C8) & TRIM(D8) -> Appeals | K8: =IFERROR(I8*60,"") -> 276.576
A9: Q4'24 | E9: Appeals | F9: Appeals | G9: Ad Group Disapproval Inquiry (Smart Assign) | I9: 7.6509 | J9: =TRIM(E9) & TRIM(C9) & TRIM(D9) -> Appeals | K9: =IFERROR(I9*60,"") -> 459.054
A10: Q4'24 | E10: Appeals | F10: Appeals | G10: Consultation | I10: 6.8944 | J10: =TRIM(E10) & TRIM(C10) & TRIM(D10) -> Appeals | K10: =IFERROR(I10*60,"") -> 413.664
A11: Q4'24 | E11: Appeals | F11: Appeals | G11: Account Disapproval Inquiry (Smart Assign) | I11: 3.682 | J11: =TRIM(E11) & TRIM(C11) & TRIM(D11) -> Appeals | K11: =IFERROR(I11*60,"") -> 220.92
A12: Q4'24 | E12: Appeals | F12: Appeals | G12: Keywords Disapproval Inquiry (Smart Assign) | I12: 3.4255 | J12: =TRIM(E12) & TRIM(C12) & TRIM(D12) -> Appeals | K12: =IFERROR(I12*60,"") -> 205.53
A13: Q4'24 | E13: Appeals | F13: Appeals | G13: Account Reminder | I13: 0.9922 | J13: =TRIM(E13) & TRIM(C13) & TRIM(D13) -> Appeals | K13: =IFERROR(I13*60,"") -> 59.532
A14: Q4'24 | E14: Appeals | F14: Appeals | G14: Product Catalog Disapproval (Smart assign) | I14: 0.0892 | J14: =TRIM(E14) & TRIM(C14) & TRIM(D14) -> Appeals | K14: =IFERROR(I14*60,"") -> 5.352
A15: Q4'24 | E15: Appeals | F15: Appeals | G15: Closed Loop Product Appeal | J15: =TRIM(E15) & TRIM(C15) & TRIM(D15) -> Appeals | K15: =IFERROR(I15*60,"") -> 0
A16: Q4'24 | E16: Appeals | F16: Appeals | G16: Other Inquiry | I16: 3.7155 | J16: =TRIM(E16) & TRIM(C16) & TRIM(D16) -> Appeals | K16: =IFERROR(I16*60,"") -> 222.93
A17: Q4'24 | E17: Appeals | F17: Appeals | G17: BC Suspension Appeal (Smart Assign) | I17: 4.6123 | J17: =TRIM(E17) & TRIM(C17) & TRIM(D17) -> Appeals | K17: =IFERROR(I17*60,"") -> 276.738
A18: Q4'24 | E18: Appeals | F18: Appeals | G18: Catalog Ads Disapproval Inquiry (Smart Assign) | I18: 4.0971 | J18: =TRIM(E18) & TRIM(C18) & TRIM(D18) -> Appeals | K18: =IFERROR(I18*60,"") -> 245.826
A19: Q4'24 | E19: Appeals | F19: Appeals | G19: Sponsored Content Appeal (Smart Assign) | I19: 15.5317 | J19: =TRIM(E19) & TRIM(C19) & TRIM(D19) -> Appeals | K19: =IFERROR(I19*60,"") -> 931.902
A20: Q4'24 | E20: Appeals | F20: Appeals | G20: Ad Group Disapproval Inquiry (DSA) | I20: 10.057 | J20: =TRIM(E20) & TRIM(C20) & TRIM(D20) -> Appeals | K20: =IFERROR(I20*60,"") -> 603.42
A21: Q4'24 | E21: Appeals | F21: Appeals | G21: Pro Account Lead Gen Disapproval Inquiry (Smart Assign) | I21: 2.9142 | J21: =TRIM(E21) & TRIM(C21) & TRIM(D21) -> Appeals | K21: =IFERROR(I21*60,"") -> 174.852
A22: Q4'24 | E22: Appeals | F22: Appeals | G22: Pro Account Registration Disapproval Inquiry (Smart Assign) | I22: 3.7672 | J22: =TRIM(E22) & TRIM(C22) & TRIM(D22) -> Appeals | K22: =IFERROR(I22*60,"") -> 226.032
A23: Q4'24 | E23: Appeals | F23: Appeals | G23: Spark BC Appeal (Smart Assign) | I23: 6.1966 | J23: =TRIM(E23) & TRIM(C23) & TRIM(D23) -> Appeals | K23: =IFERROR(I23*60,"") -> 371.796
A24: Q4'24 | E24: Appeals | F24: Appeals | G24: Pro Account Product Disapproval Inquiry (Smart Assign) | I24: 2.2576 | J24: =TRIM(E24) & TRIM(C24) & TRIM(D24) -> Appeals | K24: =IFERROR(I24*60,"") -> 135.456
A25: Q4'24 | E25: Appeals | F25: Appeals | G25: Account Soft Enforcement Appeal | I25: 4.852 | J25: =TRIM(E25) & TRIM(C25) & TRIM(D25) -> Appeals | K25: =IFERROR(I25*60,"") -> 291.12
A26: Q4'24 | E26: Appeals | F26: Appeals | G26: Qualification Disapproval Inquiry | I26: 5.1168 | J26: =TRIM(E26) & TRIM(C26) & TRIM(D26) -> Appeals | K26: =IFERROR(I26*60,"") -> 307.008
A27: Q4'24 | E27: Appeals | F27: Appeals | G27: IP Infringement Report (Smart Assign) | I27: 4.1775 | J27: =TRIM(E27) & TRIM(C27) & TRIM(D27) -> Appeals | K27: =IFERROR(I27*60,"") -> 250.65
... A36: Q4'24 | E36: Appeals | F36: Appeals | G36: Advertiser Limit for BC | I36: 5.98 | J36: =TRIM(E36) & TRIM(C36) & TRIM(D36) -> Appeals | K36: =IFERROR(I36*60,"") -> 358.8
A37: Q4'24 | B37: (空字符串) | C37: (空字符串) | D37: ["PHILIPPINES"] | E37: Others | F37: Others | G37: (空字符串)-["PHILIPPINES"] | J37: =TRIM(E37) & TRIM(C37) & TRIM(D37) -> Others(空字符串)["PHILIPPINES"] | K37: =IFERROR(I37*60,"") -> 0
A38: Q4'24 | B38: Bid Ads | C38: Bid Ad Group | D38: SG | E38: Re-review | F38: Re-review | G38: Bid Ad Group-SG | I38: 4.3904 | J38: =TRIM(E38) & TRIM(C38) & TRIM(D38) -> Re-reviewBid Ad GroupSG | K38: =IFERROR(I38*60,"") -> 263.424
A39: Q4'24 | B39: Bid Ads | C39: Bid Ecom URL | D39: CL | E39: First Review | F39: First Review | G39: Bid Ecom URL-CL | I39: 1.7407 | J39: =TRIM(E39) & TRIM(C39) & TRIM(D39) -> First ReviewBid Ecom URLCL | K39: =IFERROR(I39*60,"") -> 104.442
A40: Q4'24 | B40: Bid Ads | C40: Bid Ad Group | D40: EE | E40: Posted Recall | F40: Recall | G40: Bid Ad Group-EE | I40: 3.1858 | J40: =TRIM(E40) & TRIM(C40) & TRIM(D40) -> Posted RecallBid Ad GroupEE | K40: =IFERROR(I40*60,"") -> 191.148
A41: Q4'24 | B41: Bid Ads | C41: Bid Link | D41: BE | E41: First Review | F41: First Review | G41: Bid Link-BE | I41: 0.6947 | J41: =TRIM(E41) & TRIM(C41) & TRIM(D41) -> First ReviewBid LinkBE | K41: =IFERROR(I41*60,"") -> 41.682
A42: Q4'24 | B42: Bid Ads | C42: Bid Image | D42: IQ | E42: First Review | F42: First Review | G42: Bid Image-IQ | I42: 0.3954 | J42: =TRIM(E42) & TRIM(C42) & TRIM(D42) -> First ReviewBid ImageIQ | K42: =IFERROR(I42*60,"") -> 23.724
A43: Q4'24 | B43: Bid Ads | C43: Bid Ecom Ads Group | D43: LT | E43: Posted Recall | F43: Recall | G43: Bid Ecom Ads Group-LT | I43: 4.0945 | J43: =TRIM(E43) & TRIM(C43) & TRIM(D43) -> Posted RecallBid Ecom Ads GroupLT | K43: =IFERROR(I43*60,"") -> 245.67
A44: Q4'24 | B44: Bid Ads | C44: Bid Video | D44: ZA | E44: First Review | F44: First Review | G44: Bid Video-ZA | I44: 2.1283 | J44: =TRIM(E44) & TRIM(C44) & TRIM(D44) -> First ReviewBid VideoZA | K44: =IFERROR(I44*60,"") -> 127.698
A45: Q4'24 | B45: Bid Ads | C45: Bid Text | D45: KH | E45: First Review | F45: First Review | G45: Bid Text-KH | I45: 0.3272 | J45: =TRIM(E45) & TRIM(C45) & TRIM(D45) -> First ReviewBid TextKH | K45: =IFERROR(I45*60,"") -> 19.632
A46: Q4'24 | B46: Bid Ads | C46: Bid Ecom Video | D46: EC | E46: First Review | F46: First Review | G46: Bid Ecom Video-EC | I46: 1.3079 | J46: =TRIM(E46) & TRIM(C46) & TRIM(D46) -> First ReviewBid Ecom VideoEC | K46: =IFERROR(I46*60,"") -> 78.474
A47: Q4'24 | B47: Bid Ads | C47: Bid Ecom Ads Group | D47: AE | E47: Re-review | F47: Re-review | G47: Bid Ecom Ads Group-AE | I47: 6.8545 | J47: =TRIM(E47) & TRIM(C47) & TRIM(D47) -> Re-reviewBid Ecom Ads GroupAE | K47: =IFERROR(I47*60,"") -> 411.27
A48: Q4'24 | B48: Bid Ads | C48: Bid Link | D48: FI | E48: First Review | F48: First Review | G48: Bid Link-FI | I48: 1.2101 | J48: =TRIM(E48) & TRIM(C48) & TRIM(D48) -> First ReviewBid LinkFI | K48: =IFERROR(I48*60,"") -> 72.606
...

Sheet Team Member List
A1: Market | B1: Team Member | C1: TL Name
A2: Indonesia 🇮🇩 | B2: Ivy Tan | C2: TL Ramirez
B3: Elena Petrova | C3: TL Ramirez
B4: Tomas Novotny | C4: TL Ramirez
B5: Talia Rosen | C5: TL Ramirez
B6: Bilal Ahmadi | C6: TL Ramirez
B7: Priya Ramesh | C7: TL Ramirez
B8: Grace Osei | C8: TL Ramirez
B9: Ines Costa | C9: TL Ramirez
B10: Nadia Kowalski | C10: TL Ramirez
B11: Isabelle Laurent | C11: TL Ramirez
B12: Ravi Kapoor | C12: TL Ramirez
A13: Malaysia 🇲🇾 Singapore 🇸🇬 | B13: Hiro Sato | C13: TL Ramirez
B14: Anika Sharma | C14: TL Ramirez
B15: Bram de Vries | C15: TL Ramirez
A16: Vietnam 🇻🇳 | B16: Layla Hassan | C16: TL Lindgren
B17: Farid Rahman | C17: TL Lindgren
B18: Quinn Delacroix | C18: TL Lindgren
B19: Jonas Weber | C19: TL Lindgren
B20: Lucas Ferreira | C20: TL Lindgren
B21: Diego Alvarez | C21: TL Lindgren
B22: Haruto Kimura | C22: TL Lindgren
B23: Freya Lindqvist | C23: TL Lindgren
B24: Mira Chandra | C24: TL Lindgren
B25: Amira Haddad | C25: TL Lindgren
B26: Noah Bergstrom | C26: TL Lindgren
A27: Australia 🇦🇺 New Zealand 🇳🇿 | B27: Mei Lin Chua | C27: TL Lindgren
B28: Yuki Tanaka | C28: TL Lindgren
B29: Leo Marchetti | C29: TL Lindgren
B30: Olga Sokolova | C30: TL Lindgren
B31: Kenji Watanabe | C31: TL Lindgren
A32: Japan 🇯🇵 (JP Time) | B32: Omar Fathi | C32: TL Okafor
B33: Sanne Bakker | C33: TL Okafor
B34: Beatriz Souza | C34: TL Okafor
B35: Ingrid Larsen | C35: TL Okafor
A36: Korea 🇰🇷 | B36: Theo Andersson | C36: TL Okafor
A37: Cambodia 🇰🇭 | B37: Aleksander Kovac | C37: TL Okafor
A38: Taiwan 🇹🇼 Hong Kong 🇭🇰 | B38: Kaia Nilsen | C38: TL Okafor
B39: Wei Chen | C39: TL Okafor
B40: Mateus Silva | C40: TL Okafor
...

Sheet W47
A1: Notes: Summary of specialist AHT for tickets exceeding target (sample data)
A2: Color Scheme: RED text when AHT does not meet the WFM target
A3: Audit Stage | B3: Audit Stage | C3: Name | D3: Name (Refer) | E3: product_level1_name | F3: product_level2_name | G3: product_level2_name | H3: delivery_country | I3: Helper | J3: AHT Target (sec) (WFM) | K3: 2024-W47(11/18~11/24) | M3: Meet Target | N3: TL Name | O3: Reference Link
K4: AHT (sec) | L4: Average Video Duration (sec)
A5: First Review | C5: Nikolai Petrov | D5: Nikolai Petrov | E5: Feature Ads | F5: Highlight View | G5: Highlight View | H5: TH | I5: =TRIM(A5) & TRIM(F5) & TRIM(H5) -> First ReviewHighlight ViewTH | J5: =IFERROR(VLOOKUP(I5,'WFM Q4 Target'!J:K,2,0),"-") -> 225.126 | K5: 4278.1458 | L5: 0 | M5: =IFERROR(IF(K5>J5,"Not Meet Target","Meet Target"),"-") -> Not Meet Target | N5: =IFERROR(VLOOKUP(D5,'Team Member List'!B:C,2,0),"") -> TL Cabrera | O5: View ticket
A6: First Review | C6: Pieter Janssen | D6: Pieter Janssen | E6: Bid Ads | F6: Bid Ad Group | G6: Bid Ad Group | H6: KR | I6: =TRIM(A6) & TRIM(F6) & TRIM(H6) -> First ReviewBid Ad GroupKR | J6: =IFERROR(VLOOKUP(I6,'WFM Q4 Target'!J:K,2,0),"-") -> 136.11 | K6: 1866.8485 | L6: 1959.1291 | M6: =IFERROR(IF(K6>J6,"Not Meet Target","Meet Target"),"-") -> Not Meet Target | N6: =IFERROR(VLOOKUP(D6,'Team Member List'!B:C,2,0),"") -> TL Cabrera | O6: View ticket
A7: First Review | C7: Chloe Martin | D7: Chloe Martin | E7: Bid Ads | F7: Bid Ad Group | G7: Bid Ad Group | H7: TH | I7: =TRIM(A7) & TRIM(F7) & TRIM(H7) -> First ReviewBid Ad GroupTH | J7: =IFERROR(VLOOKUP(I7,'WFM Q4 Target'!J:K,2,0),"-") -> 99.684 | K7: 698.0773 | L7: 49.4126 | M7: =IFERROR(IF(K7>J7,"Not Meet Target","Meet Target"),"-") -> Not Meet Target | N7: =IFERROR(VLOOKUP(D7,'Team Member List'!B:C,2,0),"") -> TL Okafor | O7: View ticket
A8: First Review | C8: Jonas Weber | D8: Jonas Weber | E8: Feature Ads | F8: EST | G8: EST | H8: VN | I8: =TRIM(A8) & TRIM(F8) & TRIM(H8) -> First ReviewESTVN | J8: =IFERROR(VLOOKUP(I8,'WFM Q4 Target'!J:K,2,0),"-") -> - | K8: 624.274 | L8: 0 | M8: =IFERROR(IF(K8>J8,"Not Meet Target","Meet Target"),"-") -> Meet Target | N8: =IFERROR(VLOOKUP(D8,'Team Member List'!B:C,2,0),"") -> TL Lindgren | O8: View ticket
A9: First Review | D9: Jonas Weber | F9: Highlight View | G9: Highlight View | H9: VN | I9: =TRIM(A9) & TRIM(F9) & TRIM(H9) -> First ReviewHighlight ViewVN | J9: =IFERROR(VLOOKUP(I9,'WFM Q4 Target'!J:K,2,0),"-") -> 286.158 | K9: 1617.4814 | L9: 7.9403 | M9: =IFERROR(IF(K9>J9,"Not Meet Target","Meet Target"),"-") -> Not Meet Target | N9: =IFERROR(VLOOKUP(D9,'Team Member List'!B:C,2,0),"") -> TL Lindgren | O9: View ticket
A10: First Review | C10: Lucas Ferreira | D10: Lucas Ferreira | E10: Bid Ads | F10: Bid Ad Group | G10: Bid Ad Group | H10: VN | I10: =TRIM(A10) & TRIM(F10) & TRIM(H10) -> First ReviewBid Ad GroupVN | J10: =IFERROR(VLOOKUP(I10,'WFM Q4 Target'!J:K,2,0),"-") -> 220.83 | K10: 713.4724 | L10: 103.5137 | M10: =IFERROR(IF(K10>J10,"Not Meet Target","Meet Target"),"-") -> Not Meet Target | N10: =IFERROR(VLOOKUP(D10,'Team Member List'!B:C,2,0),"") -> TL Lindgren | O10: View ticket
A11: First Review | D11: Lucas Ferreira | E11: Feature Ads | F11: Highlight View | G11: Highlight View | H11: VN | I11: =TRIM(A11) & TRIM(F11) & TRIM(H11) -> First ReviewHighlight ViewVN | J11: =IFERROR(VLOOKUP(I11,'WFM Q4 Target'!J:K,2,0),"-") -> 286.158 | K11: 977.2672 | L11: 0 | M11: =IFERROR(IF(K11>J11,"Not Meet Target","Meet Target"),"-") -> Not Meet Target | N11: =IFERROR(VLOOKUP(D11,'Team Member List'!B:C,2,0),"") -> TL Lindgren | O11: View ticket
A12: First Review | C12: Sanne Bakker | D12: Sanne Bakker | E12: Bid Ads | F12: Bid Ecom Ads Group | G12: Bid Ecom Ads Group | H12: JP | I12: =TRIM(A12) & TRIM(F12) & TRIM(H12) -> First ReviewBid Ecom Ads GroupJP | J12: =IFERROR(VLOOKUP(I12,'WFM Q4 Target'!J:K,2,0),"-") -> 118.404 | K12: 2896.5211 | L12: 0 | M12: =IFERROR(IF(K12>J12,"Not Meet Target","Meet Target"),"-") -> Not Meet Target | N12: =IFERROR(VLOOKUP(D12,'Team Member List'!B:C,2,0),"") -> TL Okafor | O12: View ticket
A13: First Review | D13: Sanne Bakker | E13: Quest | F13: Quest Adv Video | G13: Quest Adv Video | H13: JP | I13: =TRIM(A13) & TRIM(F13) & TRIM(H13) -> First ReviewQuest Adv VideoJP | J13: =IFERROR(VLOOKUP(I13,'WFM Q4 Target'!J:K,2,0),"-") -> 11.058 | K13: 402.9425 | L13: 4.5733 | M13: =IFERROR(IF(K13>J13,"Not Meet Target","Meet Target"),"-") -> Not Meet Target | N13: =IFERROR(VLOOKUP(D13,'Team Member List'!B:C,2,0),"") -> TL Okafor | O13: View ticket
A14: First Review | C14: Camille Dubois | D14: Camille Dubois | E14: Bid Ads | F14: Bid Ad Group | G14: Bid Ad Group | H14: MY | I14: =TRIM(A14) & TRIM(F14) & TRIM(H14) -> First ReviewBid Ad GroupMY | J14: =IFERROR(VLOOKUP(I14,'WFM Q4 Target'!J:K,2,0),"-") -> 108.99 | K14: 3135.6527 | L14: 88.437 | M14: =IFERROR(IF(K14>J14,"Not Meet Target","Meet Target"),"-") -> Not Meet Target | N14: =IFERROR(VLOOKUP(D14,'Team Member List'!B:C,2,0),"") -> TL Cabrera | O14: View ticket
A15: First Review | D15: Camille Dubois | E15: Feature Ads | F15: Booking Ads Pre Approval | G15: Booking Ads Pre Approval | H15: SG | I15: =TRIM(A15) & TRIM(F15) & TRIM(H15) -> First ReviewBooking Ads Pre ApprovalSG | J15: =IFERROR(VLOOKUP(I15,'WFM Q4 Target'!J:K,2,0),"-") -> 59.52 | K15: 460.1084 | L15: 27.2474 | M15: =IFERROR(IF(K15>J15,"Not Meet Target","Meet Target"),"-") -> Not Meet Target | N15: =IFERROR(VLOOKUP(D15,'Team Member List'!B:C,2,0),"") -> TL Cabrera | O15: View ticket
A16: First Review | D16: Camille Dubois | E16: Quest | F16: HTC Adv Campaign | G16: HTC Adv Campaign | H16: PH | I16: =TRIM(A16) & TRIM(F16) & TRIM(H16) -> First ReviewHTC Adv CampaignPH | J16: =IFERROR(VLOOKUP(I16,'WFM Q4 Target'!J:K,2,0),"-") -> 142.656 | K16: 732.8054 | L16: 0 | M16: =IFERROR(IF(K16>J16,"Not Meet Target","Meet Target"),"-") -> Not Meet Target | N16: =IFERROR(VLOOKUP(D16,'Team Member List'!B:C,2,0),"") -> TL Cabrera | O16: View ticket
A17: First Review | C17: Amira Haddad | D17: Amira Haddad | E17: Bid Ads | F17: Bid Ad Group | G17: Bid Ad Group | H17: VN | I17: =TRIM(A17) & TRIM(F17) & TRIM(H17) -> First ReviewBid Ad GroupVN | J17: =IFERROR(VLOOKUP(I17,'WFM Q4 Target'!J:K,2,0),"-") -> 220.83 | K17: 407.3021 | L17: 23.0964 | M17: =IFERROR(IF(K17>J17,"Not Meet Target","Meet Target"),"-") -> Not Meet Target | N17: =IFERROR(VLOOKUP(D17,'Team Member List'!B:C,2,0),"") -> TL Lindgren | O17: View ticket
A18: First Review | C18: Mateus Silva | D18: Mateus Silva | E18: Bid Ads | F18: Bid Ad Group | G18: Bid Ad Group | H18: TW | I18: =TRIM(A18) & TRIM(F18) & TRIM(H18) -> First ReviewBid Ad GroupTW | J18: =IFERROR(VLOOKUP(I18,'WFM Q4 Target'!J:K,2,0),"-") -> 224.148 | K18: 1303.0493 | L18: 127.4836 | M18: =IFERROR(IF(K18>J18,"Not Meet Target","Meet Target"),"-") -> Not Meet Target | N18: =IFERROR(VLOOKUP(D18,'Team Member List'!B:C,2,0),"") -> TL Okafor | O18: View ticket
A19: First Review | D19: Mateus Silva | F19: Bid Link | G19: Bid Link | H19: TW | I19: =TRIM(A19) & TRIM(F19) & TRIM(H19) -> First ReviewBid LinkTW | J19: =IFERROR(VLOOKUP(I19,'WFM Q4 Target'!J:K,2,0),"-") -> 150.258 | K19: 378.5848 | L19: 0 | M19: =IFERROR(IF(K19>J19,"Not Meet Target","Meet Target"),"-") -> Not Meet Target | N19: =IFERROR(VLOOKUP(D19,'Team Member List'!B:C,2,0),"") -> TL Okafor | O19: View ticket
A20: First Review | C20: Elena Petrova | D20: Elena Petrova | E20: Bid Ads | F20: Bid Ad Group | G20: Bid Ad Group | H20: ID | I20: =TRIM(A20) & TRIM(F20) & TRIM(H20) -> First ReviewBid Ad GroupID | J20: =IFERROR(VLOOKUP(I20,'WFM Q4 Target'!J:K,2,0),"-") -> 118.062 | K20: 315.7202 | L20: 145.4062 | M20: =IFERROR(IF(K20>J20,"Not Meet Target","Meet Target"),"-") -> Not Meet Target | N20: =IFERROR(VLOOKUP(D20,'Team Member List'!B:C,2,0),"") -> TL Ramirez | O20: View ticket
A21: First Review | D21: Elena Petrova | F21: Bid Ecom Ads Group | G21: Bid Ecom Ads Group | H21: ID | I21: =TRIM(A21) & TRIM(F21) & TRIM(H21) -> First ReviewBid Ecom Ads GroupID | J21: =IFERROR(VLOOKUP(I21,'WFM Q4 Target'!J:K,2,0),"-") -> 155.28 | K21: 341.3113 | L21: 26.0491 | M21: =IFERROR(IF(K21>J21,"Not Meet Target","Meet Target"),"-") -> Not Meet Target | N21: =IFERROR(VLOOKUP(D21,'Team Member List'!B:C,2,0),"") -> TL Ramirez | O21: View ticket
A22: First Review | C22: Ines Costa | D22: Ines Costa | E22: Bid Ads | F22: Bid Ad Group | G22: Bid Ad Group | H22: CO | I22: =TRIM(A22) & TRIM(F22) & TRIM(H22) -> First ReviewBid Ad GroupCO | J22: =IFERROR(VLOOKUP(I22,'WFM Q4 Target'!J:K,2,0),"-") -> 107.178 | K22: 419.7613 | L22: 412.6696 | M22: =IFERROR(IF(K22>J22,"Not Meet Target","Meet Target"),"-") -> Not Meet Target | N22: =IFERROR(VLOOKUP(D22,'Team Member List'!B:C,2,0),"") -> TL Ramirez | O22: View ticket
A23: First Review | D23: Ines Costa | F23: Bid Ecom Ads Group | G23: Bid Ecom Ads Group | H23: AU | I23: =TRIM(A23) & TRIM(F23) & TRIM(H23) -> First ReviewBid Ecom Ads GroupAU | J23: =IFERROR(VLOOKUP(I23,'WFM Q4 Target'!J:K,2,0),"-") -> 157.866 | K23: 273.7362 | L23: 117.483 | M23: =IFERROR(IF(K23>J23,"Not Meet Target","Meet Target"),"-") -> Not Meet Target | N23: =IFERROR(VLOOKUP(D23,'Team Member List'!B:C,2,0),"") -> TL Ramirez | O23: View ticket
A24: First Review | D24: Ines Costa | E24: Feature Ads | F24: Highlight View | G24: Highlight View | H24: PK | I24: =TRIM(A24) & TRIM(F24) & TRIM(H24) -> First ReviewHighlight ViewPK | J24: =IFERROR(VLOOKUP(I24,'WFM Q4 Target'!J:K,2,0),"-") -> 778.074 | K24: 1502.5033 | L24: 0 | M24: =IFERROR(IF(K24>J24,"Not Meet Target","Meet Target"),"-") -> Not Meet Target | N24: =IFERROR(VLOOKUP(D24,'Team Member List'!B:C,2,0),"") -> TL Ramirez | O24: View ticket
A25: First Review | C25: Talia Rosen | D25: Talia Rosen | E25: Feature Ads | F25: Booking Ads Pre Approval | G25: Booking Ads Pre Approval | H25: CO | I25: =TRIM(A25) & TRIM(F25) & TRIM(H25) -> First ReviewBooking Ads Pre ApprovalCO | J25: =IFERROR(VLOOKUP(I25,'WFM Q4 Target'!J:K,2,0),"-") -> 1126.626 | K25: 1343.147 | L25: 15.6439 | M25: =IFERROR(IF(K25>J25,"Not Meet Target","Meet Target"),"-") -> Not Meet Target | N25: =IFERROR(VLOOKUP(D25,'Team Member List'!B:C,2,0),"") -> TL Ramirez | O25: View ticket
A26: First Review | D26: Talia Rosen | F26: Booking Ads Pre Approval | H26: ID | I26: =TRIM(A26) & TRIM(F26) & TRIM(H26) -> First ReviewBooking Ads Pre ApprovalID | J26: =IFERROR(VLOOKUP(I26,'WFM Q4 Target'!J:K,2,0),"-") -> 271.992 | K26: 269.2419 | L26: 7.9742 | M26: =IFERROR(IF(K26>J26,"Not Meet Target","Meet Target"),"-") -> Meet Target | N26: =IFERROR(VLOOKUP(D26,'Team Member List'!B:C,2,0),"") -> TL Ramirez | O26: View ticket
A27: First Review | D27: Talia Rosen | F27: Highlight View | G27: Highlight View | H27: ID | I27: =TRIM(A27) & TRIM(F27) & TRIM(H27) -> First ReviewHighlight ViewID | J27: =IFERROR(VLOOKUP(I27,'WFM Q4 Target'!J:K,2,0),"-") -> 590.502 | K27: 647.1086 | L27: 0 | M27: =IFERROR(IF(K27>J27,"Not Meet Target","Meet Target"),"-") -> Not Meet Target | N27: =IFERROR(VLOOKUP(D27,'Team Member List'!B:C,2,0),"") -> TL Ramirez | O27: View ticket
A28: First Review | D28: Talia Rosen | E28: Quest | F28: Quest Adv Video | G28: Quest Adv Video | H28: US | I28: =TRIM(A28) & TRIM(F28) & TRIM(H28) -> First ReviewQuest Adv VideoUS | J28: =IFERROR(VLOOKUP(I28,'WFM Q4 Target'!J:K,2,0),"-") -> 99.006 | K28: 1804.4199 | L28: 4.777 | M28: =IFERROR(IF(K28>J28,"Not Meet Target","Meet Target"),"-") -> Not Meet Target | N28: =IFERROR(VLOOKUP(D28,'Team Member List'!B:C,2,0),"") -> TL Ramirez | O28: View ticket
A29: First Review | C29: Kaia Nilsen | D29: Kaia Nilsen | E29: Bid Ads | F29: Bid Ecom Ads Group | G29: Bid Ecom Ads Group | H29: TW | I29: =TRIM(A29) & TRIM(F29) & TRIM(H29) -> First ReviewBid Ecom Ads GroupTW | J29: =IFERROR(VLOOKUP(I29,'WFM Q4 Target'!J:K,2,0),"-") -> 256.572 | K29: 945.4452 | L29: 62.5084 | M29: =IFERROR(IF(K29>J29,"Not Meet Target","Meet Target"),"-") -> Not Meet Target | N29: =IFERROR(VLOOKUP(D29,'Team Member List'!B:C,2,0),"") -> TL Okafor | O29: View ticket
A30: First Review | D30: Kaia Nilsen | E30: Feature Ads | F30: Highlight View | G30: Highlight View | H30: TW | I30: =TRIM(A30) & TRIM(F30) & TRIM(H30) -> First ReviewHighlight ViewTW | J30: =IFERROR(VLOOKUP(I30,'WFM Q4 Target'!J:K,2,0),"-") -> 261.162 | K30: 209.2389 | L30: 0 | M30: =IFERROR(IF(K30>J30,"Not Meet Target","Meet Target"),"-") -> Meet Target | N30: =IFERROR(VLOOKUP(D30,'Team Member List'!B:C,2,0),"") -> TL Okafor | O30: View ticket
A31: First Review | C31: Noah Bergstrom | D31: Noah Bergstrom | E31: Bid Ads | F31: Bid Ecom Ads Group | G31: Bid Ecom Ads Group | H31: VN | I31: =TRIM(A31) & TRIM(F31) & TRIM(H31) -> First ReviewBid Ecom Ads GroupVN | J31: =IFERROR(VLOOKUP(I31,'WFM Q4 Target'!J:K,2,0),"-") -> 414.828 | K31: 202.6333 | L31: 44.0205 | M31: =IFERROR(IF(K31>J31,"Not Meet Target","Meet Target"),"-") -> Meet Target | N31: =IFERROR(VLOOKUP(D31,'Team Member List'!B:C,2,0),"") -> TL Lindgren | O31: View ticket
A32: First Review | C32: Diego Alvarez | D32: Diego Alvarez | E32: Feature Ads | F32: Booking Ads Pre Approval | G32: Booking Ads Pre Approval | H32: VN | I32: =TRIM(A32) & TRIM(F32) & TRIM(H32) -> First ReviewBooking Ads Pre ApprovalVN | J32: =IFERROR(VLOOKUP(I32,'WFM Q4 Target'!J:K,2,0),"-") -> 213.222 | K32: 253.0166 | L32: 21.7849 | M32: =IFERROR(IF(K32>J32,"Not Meet Target","Meet Target"),"-") -> Not Meet Target | N32: =IFERROR(VLOOKUP(D32,'Team Member List'!B:C,2,0),"") -> TL Lindgren | O32: View ticket
A33: First Review | C33: Mei Lin Chua | D33: Mei Lin Chua | E33: Bid Ads | F33: Bid Ad Group | G33: Bid Ad Group | H33: AU | I33: =TRIM(A33) & TRIM(F33) & TRIM(H33) -> First ReviewBid Ad GroupAU | J33: =IFERROR(VLOOKUP(I33,'WFM Q4 Target'!J:K,2,0),"-") -> 88.71 | K33: 578.4252 | L33: 230.3409 | M33: =IFERROR(IF(K33>J33,"Not Meet Target","Meet Target"),"-") -> Not Meet Target | N33: =IFERROR(VLOOKUP(D33,'Team Member List'!B:C,2,0),"") -> TL Lindgren | O33: View ticket
A34: First Review | D34: Mei Lin Chua | E34: Feature Ads | F34: Highlight View | G34: Highlight View | H34: AE | I34: =TRIM(A34) & TRIM(F34) & TRIM(H34) -> First ReviewHighlight ViewAE | J34: =IFERROR(VLOOKUP(I34,'WFM Q4 Target'!J:K,2,0),"-") -> 6.33 | K34: 306.9859 | L34: 0 | M34: =IFERROR(IF(K34>J34,"Not Meet Target","Meet Target"),"-") -> Not Meet Target | N34: =IFERROR(VLOOKUP(D34,'Team Member List'!B:C,2,0),"") -> TL Lindgren | O34: View ticket
A35: First Review | D35: Mei Lin Chua | F35: Highlight View | H35: SA | I35: =TRIM(A35) & TRIM(F35) & TRIM(H35) -> First ReviewHighlight ViewSA | J35: =IFERROR(VLOOKUP(I35,'WFM Q4 Target'!J:K,2,0),"-") -> 778.374 | K35: 271.1107 | L35: 0 | M35: =IFERROR(IF(K35>J35,"Not Meet Target","Meet Target"),"-") -> Meet Target | N35: =IFERROR(VLOOKUP(D35,'Team Member List'!B:C,2,0),"") -> TL Lindgren | O35: View ticket
A36: First Review | C36: Theo Andersson | D36: Theo Andersson | E36: Feature Ads | F36: EST | G36: EST | H36: KR | I36: =TRIM(A36) & TRIM(F36) & TRIM(H36) -> First ReviewESTKR | J36: =IFERROR(VLOOKUP(I36,'WFM Q4 Target'!J:K,2,0),"-") -> - | K36: 178.9519 | L36: 0 | M36: =IFERROR(IF(K36>J36,"Not Meet Target","Meet Target"),"-") -> Meet Target | N36: =IFERROR(VLOOKUP(D36,'Team Member List'!B:C,2,0),"") -> TL Okafor | O36: View ticket
A37: First Review | C37: Nadia Kowalski | D37: Nadia Kowalski | E37: Bid Ads | F37: Bid Ad Group | G37: Bid Ad Group | H37: ID | I37: =TRIM(A37) & TRIM(F37) & TRIM(H37) -> First ReviewBid Ad GroupID | J37: =IFERROR(VLOOKUP(I37,'WFM Q4 Target'!J:K,2,0),"-") -> 118.062 | K37: 218.528 | L37: 162.5757 | M37: =IFERROR(IF(K37>J37,"Not Meet Target","Meet Target"),"-") -> Not Meet Target | N37: =IFERROR(VLOOKUP(D37,'Team Member List'!B:C,2,0),"") -> TL Ramirez | O37: View ticket
A38: First Review | D38: Nadia Kowalski | F38: Bid Ecom Ads Group | G38: Bid Ecom Ads Group | H38: ID | I38: =TRIM(A38) & TRIM(F38) & TRIM(H38) -> First ReviewBid Ecom Ads GroupID | J38: =IFERROR(VLOOKUP(I38,'WFM Q4 Target'!J:K,2,0),"-") -> 155.28 | K38: 460.8002 | L38: 117.0219 | M38: =IFERROR(IF(K38>J38,"Not Meet Target","Meet Target"),"-") -> Not Meet Target | N38: =IFERROR(VLOOKUP(D38,'Team Member List'!B:C,2,0),"") -> TL Ramirez | O38: View ticket
A39: First Review | C39: Sofia Novak | D39: Sofia Novak | E39: Bid Ads | F39: Bid Ad Group | G39: Bid Ad Group | H39: PH | I39: =TRIM(A39) & TRIM(F39) & TRIM(H39) -> First ReviewBid Ad GroupPH | J39: =IFERROR(VLOOKUP(I39,'WFM Q4 Target'!J:K,2,0),"-") -> 81.798 | K39: 204.2162 | L39: 121.8561 | M39: =IFERROR(IF(K39>J39,"Not Meet Target","Meet Target"),"-") -> Not Meet Target | N39: =IFERROR(VLOOKUP(D39,'Team Member List'!B:C,2,0),"") -> TL Okafor | O39: View ticket
A40: First Review | D40: Sofia Novak | F40: Bid Ecom Ads Group | G40: Bid Ecom Ads Group | H40: PH | I40: =TRIM(A40) & TRIM(F40) & TRIM(H40) -> First ReviewBid Ecom Ads GroupPH | J40: =IFERROR(VLOOKUP(I40,'WFM Q4 Target'!J:K,2,0),"-") -> 106.374 | K40: 486.1408 | L40: 35.5436 | M40: =IFERROR(IF(K40>J40,"Not Meet Target","Meet Target"),"-") -> Not Meet Target | N40: =IFERROR(VLOOKUP(D40,'Team Member List'!B:C,2,0),"") -> TL Okafor | O40: View ticket
...

Sheet W48
A1: Notes: Summary of specialist AHT for tickets exceeding target (sample data)
A2: Color Scheme: RED text when AHT does not meet the WFM target
A3: Audit Stage | B3: Audit Stage | C3: Name | D3: Name (Refer) | E3: product_level1_name | F3: product_level2_name | G3: product_level2_name | H3: delivery_country | I3: Helper | J3: AHT Target (sec) (WFM) | K3: 2024-W48(11/25~12/01) | M3: Meet Target | N3: TL Name | O3: Reference Link
K4: AHT (sec) | L4: Average Video Duration (sec)
A5: First Review | C5: Maya Santoso | D5: Maya Santoso | E5: Feature Ads | F5: Booking Ads Pre Approval | G5: Booking Ads Pre Approval | H5: MY | I5: =TRIM(A5) & TRIM(F5) & TRIM(H5) -> First ReviewBooking Ads Pre ApprovalMY | J5: =IFERROR(VLOOKUP(I5,'WFM Q4 Target'!J:K,2,0),"-") -> 91.824 | K5: 214.4682 | L5: 18.5662 | M5: =IFERROR(IF(K5>J5,"Not Meet Target","Meet Target"),"-") -> Not Meet Target | N5: =IFERROR(VLOOKUP(D5,'Team Member List'!B:C,2,0),"") -> TL Cabrera | O5: View ticket
A6: First Review | D6: Maya Santoso | F6: Booking Ads Pre Approval | H6: PH | I6: =TRIM(A6) & TRIM(F6) & TRIM(H6) -> First ReviewBooking Ads Pre ApprovalPH | J6: =IFERROR(VLOOKUP(I6,'WFM Q4 Target'!J:K,2,0),"-") -> 151.176 | K6: 282.1479 | L6: 21.6812 | M6: =IFERROR(IF(K6>J6,"Not Meet Target","Meet Target"),"-") -> Not Meet Target | N6: =IFERROR(VLOOKUP(D6,'Team Member List'!B:C,2,0),"") -> TL Cabrera | O6: View ticket
A7: First Review | D7: Maya Santoso | F7: Highlight View | G7: Highlight View | H7: PH | I7: =TRIM(A7) & TRIM(F7) & TRIM(H7) -> First ReviewHighlight ViewPH | J7: =IFERROR(VLOOKUP(I7,'WFM Q4 Target'!J:K,2,0),"-") -> 469.32 | K7: 381.2682 | L7: 157.9353 | M7: =IFERROR(IF(K7>J7,"Not Meet Target","Meet Target"),"-") -> Meet Target | N7: =IFERROR(VLOOKUP(D7,'Team Member List'!B:C,2,0),"") -> TL Cabrera | O7: View ticket
A8: First Review | D8: Maya Santoso | F8: Highlight View | H8: SG | I8: =TRIM(A8) & TRIM(F8) & TRIM(H8) -> First ReviewHighlight ViewSG | J8: =IFERROR(VLOOKUP(I8,'WFM Q4 Target'!J:K,2,0),"-") -> 225.912 | K8: 120.1627 | L8: 0 | M8: =IFERROR(IF(K8>J8,"Not Meet Target","Meet Target"),"-") -> Meet Target | N8: =IFERROR(VLOOKUP(D8,'Team Member List'!B:C,2,0),"") -> TL Cabrera | O8: View ticket
A9: First Review | D9: Maya Santoso | E9: Quest | F9: BE Adv Campaign | G9: BE Adv Campaign | H9: PH | I9: =TRIM(A9) & TRIM(F9) & TRIM(H9) -> First ReviewBE Adv CampaignPH | J9: =IFERROR(VLOOKUP(I9,'WFM Q4 Target'!J:K,2,0),"-") -> 77.454 | K9: 316.0179 | L9: 0 | M9: =IFERROR(IF(K9>J9,"Not Meet Target","Meet Target"),"-") -> Not Meet Target | N9: =IFERROR(VLOOKUP(D9,'Team Member List'!B:C,2,0),"") -> TL Cabrera | O9: View ticket
A10: First Review | D10: Maya Santoso | F10: BE Adv Video | G10: BE Adv Video | H10: PH | I10: =TRIM(A10) & TRIM(F10) & TRIM(H10) -> First ReviewBE Adv VideoPH | J10: =IFERROR(VLOOKUP(I10,'WFM Q4 Target'!J:K,2,0),"-") -> 6.606 | K10: 351.6912 | L10: 31.6412 | M10: =IFERROR(IF(K10>J10,"Not Meet Target","Meet Target"),"-") -> Not Meet Target | N10: =IFERROR(VLOOKUP(D10,'Team Member List'!B:C,2,0),"") -> TL Cabrera | O10: View ticket
A11: First Review | D11: Maya Santoso | F11: HTC Adv Campaign | G11: HTC Adv Campaign | H11: PH | I11: =TRIM(A11) & TRIM(F11) & TRIM(H11) -> First ReviewHTC Adv CampaignPH | J11: =IFERROR(VLOOKUP(I11,'WFM Q4 Target'!J:K,2,0),"-") -> 142.656 | K11: 466.1188 | L11: 0 | M11: =IFERROR(IF(K11>J11,"Not Meet Target","Meet Target"),"-") -> Not Meet Target | N11: =IFERROR(VLOOKUP(D11,'Team Member List'!B:C,2,0),"") -> TL Cabrera | O11: View ticket
A12: First Review | D12: Maya Santoso | F12: HTC Adv Video | G12: HTC Adv Video | H12: PH | I12: =TRIM(A12) & TRIM(F12) & TRIM(H12) -> First ReviewHTC Adv VideoPH | J12: =IFERROR(VLOOKUP(I12,'WFM Q4 Target'!J:K,2,0),"-") -> 29.562 | K12: 451.0152 | L12: 35.0741 | M12: =IFERROR(IF(K12>J12,"Not Meet Target","Meet Target"),"-") -> Not Meet Target | N12: =IFERROR(VLOOKUP(D12,'Team Member List'!B:C,2,0),"") -> TL Cabrera | O12: View ticket
A13: First Review | D13: Maya Santoso | F13: Quest Adv Video | G13: Quest Adv Video | H13: PH | I13: =TRIM(A13) & TRIM(F13) & TRIM(H13) -> First ReviewQuest Adv VideoPH | J13: =IFERROR(VLOOKUP(I13,'WFM Q4 Target'!J:K,2,0),"-") -> 13.278 | K13: 357.1996 | L13: 40.4655 | M13: =IFERROR(IF(K13>J13,"Not Meet Target","Meet Target"),"-") -> Not Meet Target | N13: =IFERROR(VLOOKUP(D13,'Team Member List'!B:C,2,0),"") -> TL Cabrera | O13: View ticket
A14: First Review | C14: Elena Petrova | D14: Elena Petrova | E14: Feature Ads | F14: Highlight View | G14: Highlight View | H14: CO | I14: =TRIM(A14) & TRIM(F14) & TRIM(H14) -> First ReviewHighlight ViewCO | J14: =IFERROR(VLOOKUP(I14,'WFM Q4 Target'!J:K,2,0),"-") -> 513.444 | K14: 762.4357 | L14: 0 | M14: =IFERROR(IF(K14>J14,"Not Meet Target","Meet Target"),"-") -> Not Meet Target | N14: =IFERROR(VLOOKUP(D14,'Team Member List'!B:C,2,0),"") -> TL Ramirez | O14: View ticket
A15: First Review | D15: Elena Petrova | F15: Highlight View | H15: GB | I15: =TRIM(A15) & TRIM(F15) & TRIM(H15) -> First ReviewHighlight ViewGB | J15: =IFERROR(VLOOKUP(I15,'WFM Q4 Target'!J:K,2,0),"-") -> 151.884 | K15: 731.1806 | L15: 0 | M15: =IFERROR(IF(K15>J15,"Not Meet Target","Meet Target"),"-") -> Not Meet Target | N15: =IFERROR(VLOOKUP(D15,'Team Member List'!B:C,2,0),"") -> TL Ramirez | O15: View ticket
A16: First Review | D16: Elena Petrova | F16: Highlight View | H16: ID | I16: =TRIM(A16) & TRIM(F16) & TRIM(H16) -> First ReviewHighlight ViewID | J16: =IFERROR(VLOOKUP(I16,'WFM Q4 Target'!J:K,2,0),"-") -> 590.502 | K16: 156.6612 | L16: 7.7121 | M16: =IFERROR(IF(K16>J16,"Not Meet Target","Meet Target"),"-") -> Meet Target | N16: =IFERROR(VLOOKUP(D16,'Team Member List'!B:C,2,0),"") -> TL Ramirez | O16: View ticket
A17: First Review | C17: Yuki Tanaka | D17: Yuki Tanaka | E17: Feature Ads | F17: Booking Ads Pre Approval | G17: Booking Ads Pre Approval | H17: BR | I17: =TRIM(A17) & TRIM(F17) & TRIM(H17) -> First ReviewBooking Ads Pre ApprovalBR | J17: =IFERROR(VLOOKUP(I17,'WFM Q4 Target'!J:K,2,0),"-") -> 1137.432 | K17: 125.6088 | L17: 73.83 | M17: =IFERROR(IF(K17>J17,"Not Meet Target","Meet Target"),"-") -> Meet Target | N17: =IFERROR(VLOOKUP(D17,'Team Member List'!B:C,2,0),"") -> TL Lindgren | O17: View ticket
A18: First Review | C18: Andres Molina | D18: Andres Molina | E18: Feature Ads | F18: Highlight View | G18: Highlight View | H18: CL | I18: =TRIM(A18) & TRIM(F18) & TRIM(H18) -> First ReviewHighlight ViewCL | J18: =IFERROR(VLOOKUP(I18,'WFM Q4 Target'!J:K,2,0),"-") -> 677.166 | K18: 1981.8708 | L18: 0 | M18: =IFERROR(IF(K18>J18,"Not Meet Target","Meet Target"),"-") -> Not Meet Target | N18: =IFERROR(VLOOKUP(D18,'Team Member List'!B:C,2,0),"") -> TL Cabrera | O18: View ticket
A19: First Review | C19: Nadia Kowalski | D19: Nadia Kowalski | E19: Bid Ads | F19: Bid Ad Group | G19: Bid Ad Group | H19: ID | I19: =TRIM(A19) & TRIM(F19) & TRIM(H19) -> First ReviewBid Ad GroupID | J19: =IFERROR(VLOOKUP(I19,'WFM Q4 Target'!J:K,2,0),"-") -> 118.062 | K19: 147.8476 | L19: 121.144 | M19: =IFERROR(IF(K19>J19,"Not Meet Target","Meet Target"),"-") -> Not Meet Target | N19: =IFERROR(VLOOKUP(D19,'Team Member List'!B:C,2,0),"") -> TL Ramirez | O19: View ticket
A20: First Review | D20: Nadia Kowalski | F20: Bid Video | G20: Bid Video | H20: ID | I20: =TRIM(A20) & TRIM(F20) & TRIM(H20) -> First ReviewBid VideoID | J20: =IFERROR(VLOOKUP(I20,'WFM Q4 Target'!J:K,2,0),"-") -> 71.064 | K20: 142.4999 | L20: 202.87 | M20: =IFERROR(IF(K20>J20,"Not Meet Target","Meet Target"),"-") -> Not Meet Target | N20: =IFERROR(VLOOKUP(D20,'Team Member List'!B:C,2,0),"") -> TL Ramirez | O20: View ticket
A21: First Review | D21: Nadia Kowalski | E21: Feature Ads | F21: Booking Ads Pre Approval | G21: Booking Ads Pre Approval | H21: ID | I21: =TRIM(A21) & TRIM(F21) & TRIM(H21) -> First ReviewBooking Ads Pre ApprovalID | J21: =IFERROR(VLOOKUP(I21,'WFM Q4 Target'!J:K,2,0),"-") -> 271.992 | K21: 215.7852 | L21: 11.4765 | M21: =IFERROR(IF(K21>J21,"Not Meet Target","Meet Target"),"-") -> Meet Target | N21: =IFERROR(VLOOKUP(D21,'Team Member List'!B:C,2,0),"") -> TL Ramirez | O21: View ticket
A22: First Review | D22: Nadia Kowalski | F22: Highlight View | G22: Highlight View | H22: ID | I22: =TRIM(A22) & TRIM(F22) & TRIM(H22) -> First ReviewHighlight ViewID | J22: =IFERROR(VLOOKUP(I22,'WFM Q4 Target'!J:K,2,0),"-") -> 590.502 | K22: 194.5777 | L22: 5.1173 | M22: =IFERROR(IF(K22>J22,"Not Meet Target","Meet Target"),"-") -> Meet Target | N22: =IFERROR(VLOOKUP(D22,'Team Member List'!B:C,2,0),"") -> TL Ramirez | O22: View ticket
A23: First Review | D23: Nadia Kowalski | E23: Editorial Ads | F23: FX Studio | G23: FX Studio | H23: ID | I23: =TRIM(A23) & TRIM(F23) & TRIM(H23) -> First ReviewFX StudioID | J23: =IFERROR(VLOOKUP(I23,'WFM Q4 Target'!J:K,2,0),"-") -> - | K23: 260.6349 | L23: 10.2397 | M23: =IFERROR(IF(K23>J23,"Not Meet Target","Meet Target"),"-") -> Meet Target | N23: =IFERROR(VLOOKUP(D23,'Team Member List'!B:C,2,0),"") -> TL Ramirez | O23: View ticket
A24: First Review | C24: Paolo Ricci | D24: Paolo Ricci | E24: Feature Ads | F24: Booking Ads Pre Approval | G24: Booking Ads Pre Approval | H24: KH | I24: =TRIM(A24) & TRIM(F24) & TRIM(H24) -> First ReviewBooking Ads Pre ApprovalKH | J24: =IFERROR(VLOOKUP(I24,'WFM Q4 Target'!J:K,2,0),"-") -> 179.94 | K24: 501.553 | L24: 16.3442 | M24: =IFERROR(IF(K24>J24,"Not Meet Target","Meet Target"),"-") -> Not Meet Target | N24: =IFERROR(VLOOKUP(D24,'Team Member List'!B:C,2,0),"") -> TL Cabrera | O24: View ticket
A25: First Review | D25: Paolo Ricci | F25: Highlight View | G25: Highlight View | H25: PH | I25: =TRIM(A25) & TRIM(F25) & TRIM(H25) -> First ReviewHighlight ViewPH | J25: =IFERROR(VLOOKUP(I25,'WFM Q4 Target'!J:K,2,0),"-") -> 469.32 | K25: 185.2313 | L25: 184.4357 | M25: =IFERROR(IF(K25>J25,"Not Meet Target","Meet Target"),"-") -> Meet Target | N25: =IFERROR(VLOOKUP(D25,'Team Member List'!B:C,2,0),"") -> TL Cabrera | O25: View ticket
A26: First Review | C26: Giulia Romano | D26: Giulia Romano | E26: Bid Ads | F26: Bid Ad Group | G26: Bid Ad Group | H26: TH | I26: =TRIM(A26) & TRIM(F26) & TRIM(H26) -> First ReviewBid Ad GroupTH | J26: =IFERROR(VLOOKUP(I26,'WFM Q4 Target'!J:K,2,0),"-") -> 99.684 | K26: 272.6248 | L26: 373.3113 | M26: =IFERROR(IF(K26>J26,"Not Meet Target","Meet Target"),"-") -> Not Meet Target | N26: =IFERROR(VLOOKUP(D26,'Team Member List'!B:C,2,0),"") -> TL Cabrera | O26: View ticket
A27: First Review | C27: Camille Dubois | D27: Camille Dubois | E27: Feature Ads | F27: Booking Ads Pre Approval | G27: Booking Ads Pre Approval | H27: SG | I27: =TRIM(A27) & TRIM(F27) & TRIM(H27) -> First ReviewBooking Ads Pre ApprovalSG | J27: =IFERROR(VLOOKUP(I27,'WFM Q4 Target'!J:K,2,0),"-") -> 59.52 | K27: 4215.6333 | L27: 17.6391 | M27: =IFERROR(IF(K27>J27,"Not Meet Target","Meet Target"),"-") -> Not Meet Target | N27: =IFERROR(VLOOKUP(D27,'Team Member List'!B:C,2,0),"") -> TL Cabrera | O27: View ticket
A28: First Review | D28: Camille Dubois | F28: Booking Ads Pre Approval | H28: TR | I28: =TRIM(A28) & TRIM(F28) & TRIM(H28) -> First ReviewBooking Ads Pre ApprovalTR | J28: =IFERROR(VLOOKUP(I28,'WFM Q4 Target'!J:K,2,0),"-") -> 79.158 | K28: 184.5435 | L28: 32.4543 | M28: =IFERROR(IF(K28>J28,"Not Meet Target","Meet Target"),"-") -> Not Meet Target | N28: =IFERROR(VLOOKUP(D28,'Team Member List'!B:C,2,0),"") -> TL Cabrera | O28: View ticket
A29: First Review | D29: Camille Dubois | F29: Highlight View | G29: Highlight View | H29: PH | I29: =TRIM(A29) & TRIM(F29) & TRIM(H29) -> First ReviewHighlight ViewPH | J29: =IFERROR(VLOOKUP(I29,'WFM Q4 Target'!J:K,2,0),"-") -> 469.32 | K29: 1150.8605 | L29: 0 | M29: =IFERROR(IF(K29>J29,"Not Meet Target","Meet Target"),"-") -> Not Meet Target | N29: =IFERROR(VLOOKUP(D29,'Team Member List'!B:C,2,0),"") -> TL Cabrera | O29: View ticket
A30: First Review | D30: Camille Dubois | E30: Quest | F30: BE Adv Video | G30: BE Adv Video | H30: PH | I30: =TRIM(A30) & TRIM(F30) & TRIM(H30) -> First ReviewBE Adv VideoPH | J30: =IFERROR(VLOOKUP(I30,'WFM Q4 Target'!J:K,2,0),"-") -> 6.606 | K30: 364.4566 | L30: 13.3572 | M30: =IFERROR(IF(K30>J30,"Not Meet Target","Meet Target"),"-") -> Not Meet Target | N30: =IFERROR(VLOOKUP(D30,'Team Member List'!B:C,2,0),"") -> TL Cabrera | O30: View ticket
A31: First Review | C31: Rafael Torres | D31: Rafael Torres | E31: Feature Ads | F31: Booking Ads Pre Approval | G31: Booking Ads Pre Approval | H31: TH | I31: =TRIM(A31) & TRIM(F31) & TRIM(H31) -> First ReviewBooking Ads Pre ApprovalTH | J31: =IFERROR(VLOOKUP(I31,'WFM Q4 Target'!J:K,2,0),"-") -> 84.51 | K31: 142.4707 | L31: 22.0158 | M31: =IFERROR(IF(K31>J31,"Not Meet Target","Meet Target"),"-") -> Not Meet Target | N31: =IFERROR(VLOOKUP(D31,'Team Member List'!B:C,2,0),"") -> TL Okafor | O31: View ticket
A32: First Review | C32: Kenji Watanabe | D32: Kenji Watanabe | E32: Bid Ads | F32: Bid Ecom Ads Group | G32: Bid Ecom Ads Group | H32: AU | I32: =TRIM(A32) & TRIM(F32) & TRIM(H32) -> First ReviewBid Ecom Ads GroupAU | J32: =IFERROR(VLOOKUP(I32,'WFM Q4 Target'!J:K,2,0),"-") -> 157.866 | K32: 480.3002 | L32: 24.3736 | M32: =IFERROR(IF(K32>J32,"Not Meet Target","Meet Target"),"-") -> Not Meet Target | N32: =IFERROR(VLOOKUP(D32,'Team Member List'!B:C,2,0),"") -> TL Lindgren | O32: View ticket
A33: First Review | D33: Kenji Watanabe | E33: Feature Ads | F33: Booking Ads Pre Approval | G33: Booking Ads Pre Approval | H33: AU | I33: =TRIM(A33) & TRIM(F33) & TRIM(H33) -> First ReviewBooking Ads Pre ApprovalAU | J33: =IFERROR(VLOOKUP(I33,'WFM Q4 Target'!J:K,2,0),"-") -> 174.66 | K33: 130.1958 | L33: 48.7343 | M33: =IFERROR(IF(K33>J33,"Not Meet Target","Meet Target"),"-") -> Meet Target | N33: =IFERROR(VLOOKUP(D33,'Team Member List'!B:C,2,0),"") -> TL Lindgren | O33: View ticket
A34: First Review | D34: Kenji Watanabe | F34: Booking Ads Pre Approval | H34: TR | I34: =TRIM(A34) & TRIM(F34) & TRIM(H34) -> First ReviewBooking Ads Pre ApprovalTR | J34: =IFERROR(VLOOKUP(I34,'WFM Q4 Target'!J:K,2,0),"-") -> 79.158 | K34: 1310.8278 | L34: 18.0585 | M34: =IFERROR(IF(K34>J34,"Not Meet Target","Meet Target"),"-") -> Not Meet Target | N34: =IFERROR(VLOOKUP(D34,'Team Member List'!B:C,2,0),"") -> TL Lindgren | O34: View ticket
A35: First Review | D35: Kenji Watanabe | F35: Highlight View | G35: Highlight View | H35: MX | I35: =TRIM(A35) & TRIM(F35) & TRIM(H35) -> First ReviewHighlight ViewMX | J35: =IFERROR(VLOOKUP(I35,'WFM Q4 Target'!J:K,2,0),"-") -> 573.366 | K35: 200.0048 | L35: 0 | M35: =IFERROR(IF(K35>J35,"Not Meet Target","Meet Target"),"-") -> Meet Target | N35: =IFERROR(VLOOKUP(D35,'Team Member List'!B:C,2,0),"") -> TL Lindgren | O35: View ticket
A36: First Review | D36: Kenji Watanabe | F36: Highlight View | H36: SA | I36: =TRIM(A36) & TRIM(F36) & TRIM(H36) -> First ReviewHighlight ViewSA | J36: =IFERROR(VLOOKUP(I36,'WFM Q4 Target'!J:K,2,0),"-") -> 778.374 | K36: 441.1748 | L36: 0 | M36: =IFERROR(IF(K36>J36,"Not Meet Target","Meet Target"),"-") -> Meet Target | N36: =IFERROR(VLOOKUP(D36,'Team Member List'!B:C,2,0),"") -> TL Lindgren | O36: View ticket
A37: First Review | C37: Felix Brandt | D37: Felix Brandt | E37: Feature Ads | F37: Media Ads | G37: Media Ads | H37: TH | I37: =TRIM(A37) & TRIM(F37) & TRIM(H37) -> First ReviewMedia AdsTH | J37: =IFERROR(VLOOKUP(I37,'WFM Q4 Target'!J:K,2,0),"-") -> - | K37: 215.6858 | L37: 0 | M37: =IFERROR(IF(K37>J37,"Not Meet Target","Meet Target"),"-") -> Meet Target | N37: =IFERROR(VLOOKUP(D37,'Team Member List'!B:C,2,0),"") -> TL Okafor | O37: View ticket
A38: First Review | D38: Felix Brandt | F38: Booking Ads Pre Approval | G38: Booking Ads Pre Approval | H38: KH | I38: =TRIM(A38) & TRIM(F38) & TRIM(H38) -> First ReviewBooking Ads Pre ApprovalKH | J38: =IFERROR(VLOOKUP(I38,'WFM Q4 Target'!J:K,2,0),"-") -> 179.94 | K38: 784.0086 | L38: 13.6212 | M38: =IFERROR(IF(K38>J38,"Not Meet Target","Meet Target"),"-") -> Not Meet Target | N38: =IFERROR(VLOOKUP(D38,'Team Member List'!B:C,2,0),"") -> TL Okafor | O38: View ticket
A39: First Review | D39: Felix Brandt | F39: Highlight View | G39: Highlight View | H39: MX | I39: =TRIM(A39) & TRIM(F39) & TRIM(H39) -> First ReviewHighlight ViewMX | J39: =IFERROR(VLOOKUP(I39,'WFM Q4 Target'!J:K,2,0),"-") -> 573.366 | K39: 514.3632 | L39: 0 | M39: =IFERROR(IF(K39>J39,"Not Meet Target","Meet Target"),"-") -> Meet Target | N39: =IFERROR(VLOOKUP(D39,'Team Member List'!B:C,2,0),"") -> TL Okafor | O39: View ticket
A40: First Review | D40: Felix Brandt | E40: Quest | F40: Quest Adv Video | G40: Quest Adv Video | H40: PH | I40: =TRIM(A40) & TRIM(F40) & TRIM(H40) -> First ReviewQuest Adv VideoPH | J40: =IFERROR(VLOOKUP(I40,'WFM Q4 Target'!J:K,2,0),"-") -> 13.278 | K40: 124.9605 | L40: 16.9869 | M40: =IFERROR(IF(K40>J40,"Not Meet Target","Meet Target"),"-") -> Not Meet Target | N40: =IFERROR(VLOOKUP(D40,'Team Member List'!B:C,2,0),"") -> TL Okafor | O40: View ticket
...

Sheet W49
A1: Notes: Summary of specialist AHT for tickets exceeding target (sample data)
A2: Color Scheme: RED text when AHT does not meet the WFM target
A3: Audit Stage | B3: Audit Stage | C3: Name | D3: Name (Refer) | E3: product_level1_name | F3: product_level2_name | G3: product_level2_name | H3: delivery_country | I3: Helper | J3: AHT Target (sec) (WFM) | K3: 2024-W49(12/02~12/08) | M3: Meet Target | N3: TL Name | O3: Reference Link
K4: AHT (sec) | L4: Average Video Duration (sec)
A5: First Review | C5: Farid Rahman | D5: Farid Rahman | E5: Bid Ads | F5: Bid Ad Group | G5: Bid Ad Group | H5: VN | I5: =TRIM(A5) & TRIM(F5) & TRIM(H5) -> First ReviewBid Ad GroupVN | J5: =IFERROR(VLOOKUP(I5,'WFM Q4 Target'!J:K,2,0),"-") -> 220.83 | K5: 788.036 | L5: 62.3131 | M5: =IFERROR(IF(K5>J5,"Not Meet Target","Meet Target"),"-") -> Not Meet Target | N5: =IFERROR(VLOOKUP(D5,'Team Member List'!B:C,2,0),"") -> TL Lindgren | O5: View ticket
A6: First Review | D6: Farid Rahman | E6: Quest | F6: Quest Adv Campaign | G6: Quest Adv Campaign | H6: VN | I6: =TRIM(A6) & TRIM(F6) & TRIM(H6) -> First ReviewQuest Adv CampaignVN | J6: =IFERROR(VLOOKUP(I6,'WFM Q4 Target'!J:K,2,0),"-") -> 744.528 | K6: 321.7689 | L6: 0 | M6: =IFERROR(IF(K6>J6,"Not Meet Target","Meet Target"),"-") -> Meet Target | N6: =IFERROR(VLOOKUP(D6,'Team Member List'!B:C,2,0),"") -> TL Lindgren | O6: View ticket
A7: First Review | C7: Zara Iqbal | D7: Zara Iqbal | E7: Bid Ads | F7: Bid Ad Group | G7: Bid Ad Group | H7: PH | I7: =TRIM(A7) & TRIM(F7) & TRIM(H7) -> First ReviewBid Ad GroupPH | J7: =IFERROR(VLOOKUP(I7,'WFM Q4 Target'!J:K,2,0),"-") -> 81.798 | K7: 629.0067 | L7: 108.8914 | M7: =IFERROR(IF(K7>J7,"Not Meet Target","Meet Target"),"-") -> Not Meet Target | N7: =IFERROR(VLOOKUP(D7,'Team Member List'!B:C,2,0),"") -> TL Okafor | O7: View ticket
A8: First Review | D8: Zara Iqbal | E8: Feature Ads | F8: Highlight View | G8: Highlight View | H8: ES | I8: =TRIM(A8) & TRIM(F8) & TRIM(H8) -> First ReviewHighlight ViewES | J8: =IFERROR(VLOOKUP(I8,'WFM Q4 Target'!J:K,2,0),"-") -> 168.468 | K8: 484.0649 | L8: 0 | M8: =IFERROR(IF(K8>J8,"Not Meet Target","Meet Target"),"-") -> Not Meet Target | N8: =IFERROR(VLOOKUP(D8,'Team Member List'!B:C,2,0),"") -> TL Okafor | O8: View ticket
A9: First Review | D9: Zara Iqbal | G9: Highlight View | H9: JP | I9: =TRIM(A9) & TRIM(F9) & TRIM(H9) -> First ReviewJP | J9: =IFERROR(VLOOKUP(I9,'WFM Q4 Target'!J:K,2,0),"-") -> - | K9: 458.0081 | L9: 0 | M9: =IFERROR(IF(K9>J9,"Not Meet Target","Meet Target"),"-") -> Meet Target | N9: =IFERROR(VLOOKUP(D9,'Team Member List'!B:C,2,0),"") -> TL Okafor | O9: View ticket
A10: First Review | C10: Theo Andersson | D10: Theo Andersson | E10: Bid Ads | F10: Bid Ad Group | G10: Bid Ad Group | H10: KR | I10: =TRIM(A10) & TRIM(F10) & TRIM(H10) -> First ReviewBid Ad GroupKR | J10: =IFERROR(VLOOKUP(I10,'WFM Q4 Target'!J:K,2,0),"-") -> 136.11 | K10: 394.8184 | L10: 818.5854 | M10: =IFERROR(IF(K10>J10,"Not Meet Target","Meet Target"),"-") -> Not Meet Target | N10: =IFERROR(VLOOKUP(D10,'Team Member List'!B:C,2,0),"") -> TL Okafor | O10: View ticket
A11: First Review | D11: Theo Andersson | E11: Boost | F11: Boost Video | G11: Boost Video | H11: KR | I11: =TRIM(A11) & TRIM(F11) & TRIM(H11) -> First ReviewBoost VideoKR | J11: =IFERROR(VLOOKUP(I11,'WFM Q4 Target'!J:K,2,0),"-") -> 191.058 | K11: 133.3257 | L11: 132.1679 | M11: =IFERROR(IF(K11>J11,"Not Meet Target","Meet Target"),"-") -> Meet Target | N11: =IFERROR(VLOOKUP(D11,'Team Member List'!B:C,2,0),"") -> TL Okafor | O11: View ticket
A12: First Review | C12: Ivy Tan | D12: Ivy Tan | E12: Feature Ads | F12: Reach & Frequency | G12: Reach & Frequency | H12: ID | I12: =TRIM(A12) & TRIM(F12) & TRIM(H12) -> First ReviewReach & FrequencyID | J12: =IFERROR(VLOOKUP(I12,'WFM Q4 Target'!J:K,2,0),"-") -> - | K12: 633.6944 | L12: 172.3822 | M12: =IFERROR(IF(K12>J12,"Not Meet Target","Meet Target"),"-") -> Meet Target | N12: =IFERROR(VLOOKUP(D12,'Team Member List'!B:C,2,0),"") -> TL Ramirez | O12: View ticket
A13: First Review | D13: Ivy Tan | F13: Booking Ads Pre Approval | G13: Booking Ads Pre Approval | H13: ID | I13: =TRIM(A13) & TRIM(F13) & TRIM(H13) -> First ReviewBooking Ads Pre ApprovalID | J13: =IFERROR(VLOOKUP(I13,'WFM Q4 Target'!J:K,2,0),"-") -> 271.992 | K13: 148.7059 | L13: 13.2176 | M13: =IFERROR(IF(K13>J13,"Not Meet Target","Meet Target"),"-") -> Meet Target | N13: =IFERROR(VLOOKUP(D13,'Team Member List'!B:C,2,0),"") -> TL Ramirez | O13: View ticket
A14: First Review | D14: Ivy Tan | F14: Highlight View | G14: Highlight View | H14: ID | I14: =TRIM(A14) & TRIM(F14) & TRIM(H14) -> First ReviewHighlight ViewID | J14: =IFERROR(VLOOKUP(I14,'WFM Q4 Target'!J:K,2,0),"-") -> 590.502 | K14: 123.8955 | L14: 0 | M14: =IFERROR(IF(K14>J14,"Not Meet Target","Meet Target"),"-") -> Meet Target | N14: =IFERROR(VLOOKUP(D14,'Team Member List'!B:C,2,0),"") -> TL Ramirez | O14: View ticket
A15: First Review | D15: Ivy Tan | G15: Highlight View | H15: MX | I15: =TRIM(A15) & TRIM(F15) & TRIM(H15) -> First ReviewMX | J15: =IFERROR(VLOOKUP(I15,'WFM Q4 Target'!J:K,2,0),"-") -> - | K15: 228.2878 | L15: 0 | M15: =IFERROR(IF(K15>J15,"Not Meet Target","Meet Target"),"-") -> Meet Target | N15: =IFERROR(VLOOKUP(D15,'Team Member List'!B:C,2,0),"") -> TL Ramirez | O15: View ticket
A16: First Review | D16: Ivy Tan | E16: Quest | F16: HTC Adv Video | G16: HTC Adv Video | H16: ID | I16: =TRIM(A16) & TRIM(F16) & TRIM(H16) -> First ReviewHTC Adv VideoID | J16: =IFERROR(VLOOKUP(I16,'WFM Q4 Target'!J:K,2,0),"-") -> - | K16: 102.1364 | L16: 10.4567 | M16: =IFERROR(IF(K16>J16,"Not Meet Target","Meet Target"),"-") -> Meet Target | N16: =IFERROR(VLOOKUP(D16,'Team Member List'!B:C,2,0),"") -> TL Ramirez | O16: View ticket
A17: First Review | C17: Bram de Vries | D17: Bram de Vries | E17: Bid Ads | F17: Bid Ecom Ads Group | G17: Bid Ecom Ads Group | H17: MY | I17: =TRIM(A17) & TRIM(F17) & TRIM(H17) -> First ReviewBid Ecom Ads GroupMY | J17: =IFERROR(VLOOKUP(I17,'WFM Q4 Target'!J:K,2,0),"-") -> 148.482 | K17: 892.1653 | L17: 903.7876 | M17: =IFERROR(IF(K17>J17,"Not Meet Target","Meet Target"),"-") -> Not Meet Target | N17: =IFERROR(VLOOKUP(D17,'Team Member List'!B:C,2,0),"") -> TL Ramirez | O17: View ticket
A18: First Review | C18: Felix Brandt | D18: Felix Brandt | E18: Bid Ads | F18: Bid Ad Group | G18: Bid Ad Group | H18: BR | I18: =TRIM(A18) & TRIM(F18) & TRIM(H18) -> First ReviewBid Ad GroupBR | J18: =IFERROR(VLOOKUP(I18,'WFM Q4 Target'!J:K,2,0),"-") -> 89.562 | K18: 249.236 | L18: 60.7207 | M18: =IFERROR(IF(K18>J18,"Not Meet Target","Meet Target"),"-") -> Not Meet Target | N18: =IFERROR(VLOOKUP(D18,'Team Member List'!B:C,2,0),"") -> TL Okafor | O18: View ticket
A19: First Review | D19: Felix Brandt | E19: Feature Ads | F19: Highlight View | G19: Highlight View | H19: DE | I19: =TRIM(A19) & TRIM(F19) & TRIM(H19) -> First ReviewHighlight ViewDE | J19: =IFERROR(VLOOKUP(I19,'WFM Q4 Target'!J:K,2,0),"-") -> 682.752 | K19: 325.992 | L19: 0 | M19: =IFERROR(IF(K19>J19,"Not Meet Target","Meet Target"),"-") -> Meet Target | N19: =IFERROR(VLOOKUP(D19,'Team Member List'!B:C,2,0),"") -> TL Okafor | O19: View ticket
A20: First Review | D20: Felix Brandt | G20: Highlight View | H20: PH | I20: =TRIM(A20) & TRIM(F20) & TRIM(H20) -> First ReviewPH | J20: =IFERROR(VLOOKUP(I20,'WFM Q4 Target'!J:K,2,0),"-") -> - | K20: 250.9842 | L20: 0 | M20: =IFERROR(IF(K20>J20,"Not Meet Target","Meet Target"),"-") -> Meet Target | N20: =IFERROR(VLOOKUP(D20,'Team Member List'!B:C,2,0),"") -> TL Okafor | O20: View ticket
A21: First Review | C21: Anika Sharma | D21: Anika Sharma | E21: Feature Ads | F21: Highlight View | G21: Highlight View | H21: TW | I21: =TRIM(A21) & TRIM(F21) & TRIM(H21) -> First ReviewHighlight ViewTW | J21: =IFERROR(VLOOKUP(I21,'WFM Q4 Target'!J:K,2,0),"-") -> 261.162 | K21: 225.8041 | L21: 0 | M21: =IFERROR(IF(K21>J21,"Not Meet Target","Meet Target"),"-") -> Meet Target | N21: =IFERROR(VLOOKUP(D21,'Team Member List'!B:C,2,0),"") -> TL Ramirez | O21: View ticket
A22: First Review | C22: Priya Ramesh | D22: Priya Ramesh | E22: Quest | F22: Quest Adv Video | G22: Quest Adv Video | H22: ID | I22: =TRIM(A22) & TRIM(F22) & TRIM(H22) -> First ReviewQuest Adv VideoID | J22: =IFERROR(VLOOKUP(I22,'WFM Q4 Target'!J:K,2,0),"-") -> 49.086 | K22: 106.594 | L22: 14.1962 | M22: =IFERROR(IF(K22>J22,"Not Meet Target","Meet Target"),"-") -> Not Meet Target | N22: =IFERROR(VLOOKUP(D22,'Team Member List'!B:C,2,0),"") -> TL Ramirez | O22: View ticket
A23: First Review | C23: Mei Lin Chua | D23: Mei Lin Chua | E23: Feature Ads | F23: Highlight View | G23: Highlight View | H23: GB | I23: =TRIM(A23) & TRIM(F23) & TRIM(H23) -> First ReviewHighlight ViewGB | J23: =IFERROR(VLOOKUP(I23,'WFM Q4 Target'!J:K,2,0),"-") -> 151.884 | K23: 158.9864 | L23: 0 | M23: =IFERROR(IF(K23>J23,"Not Meet Target","Meet Target"),"-") -> Not Meet Target | N23: =IFERROR(VLOOKUP(D23,'Team Member List'!B:C,2,0),"") -> TL Lindgren | O23: View ticket
A24: First Review | C24: Jonas Weber | D24: Jonas Weber | E24: Bid Ads | F24: Bid Ad Group | G24: Bid Ad Group | H24: VN | I24: =TRIM(A24) & TRIM(F24) & TRIM(H24) -> First ReviewBid Ad GroupVN | J24: =IFERROR(VLOOKUP(I24,'WFM Q4 Target'!J:K,2,0),"-") -> 220.83 | K24: 201.3463 | L24: 116.9452 | M24: =IFERROR(IF(K24>J24,"Not Meet Target","Meet Target"),"-") -> Meet Target | N24: =IFERROR(VLOOKUP(D24,'Team Member List'!B:C,2,0),"") -> TL Lindgren | O24: View ticket
A25: First Review | D25: Jonas Weber | E25: Feature Ads | F25: Booking Ads Pre Approval | G25: Booking Ads Pre Approval | H25: VN | I25: =TRIM(A25) & TRIM(F25) & TRIM(H25) -> First ReviewBooking Ads Pre ApprovalVN | J25: =IFERROR(VLOOKUP(I25,'WFM Q4 Target'!J:K,2,0),"-") -> 213.222 | K25: 2805.3522 | L25: 40.6546 | M25: =IFERROR(IF(K25>J25,"Not Meet Target","Meet Target"),"-") -> Not Meet Target | N25: =IFERROR(VLOOKUP(D25,'Team Member List'!B:C,2,0),"") -> TL Lindgren | O25: View ticket
A26: First Review | C26: Layla Hassan | D26: Layla Hassan | E26: Feature Ads | F26: Highlight View | G26: Highlight View | H26: CL | I26: =TRIM(A26) & TRIM(F26) & TRIM(H26) -> First ReviewHighlight ViewCL | J26: =IFERROR(VLOOKUP(I26,'WFM Q4 Target'!J:K,2,0),"-") -> 677.166 | K26: 619.1511 | L26: 0 | M26: =IFERROR(IF(K26>J26,"Not Meet Target","Meet Target"),"-") -> Meet Target | N26: =IFERROR(VLOOKUP(D26,'Team Member List'!B:C,2,0),"") -> TL Lindgren | O26: View ticket
A27: First Review | C27: Aleksander Kovac | D27: Aleksander Kovac | E27: Feature Ads | F27: Highlight View | G27: Highlight View | H27: GB | I27: =TRIM(A27) & TRIM(F27) & TRIM(H27) -> First ReviewHighlight ViewGB | J27: =IFERROR(VLOOKUP(I27,'WFM Q4 Target'!J:K,2,0),"-") -> 151.884 | K27: 397.729 | L27: 0 | M27: =IFERROR(IF(K27>J27,"Not Meet Target","Meet Target"),"-") -> Not Meet Target | N27: =IFERROR(VLOOKUP(D27,'Team Member List'!B:C,2,0),"") -> TL Okafor | O27: View ticket
A28: First Review | C28: Kaia Nilsen | D28: Kaia Nilsen | E28: Bid Ads | F28: Bid Ad Group | G28: Bid Ad Group | H28: TW | I28: =TRIM(A28) & TRIM(F28) & TRIM(H28) -> First ReviewBid Ad GroupTW | J28: =IFERROR(VLOOKUP(I28,'WFM Q4 Target'!J:K,2,0),"-") -> 224.148 | K28: 276.7865 | L28: 15.2823 | M28: =IFERROR(IF(K28>J28,"Not Meet Target","Meet Target"),"-") -> Not Meet Target | N28: =IFERROR(VLOOKUP(D28,'Team Member List'!B:C,2,0),"") -> TL Okafor | O28: View ticket
A29: First Review | D29: Kaia Nilsen | E29: Feature Ads | F29: Booking Ads Pre Approval | G29: Booking Ads Pre Approval | H29: TW | I29: =TRIM(A29) & TRIM(F29) & TRIM(H29) -> First ReviewBooking Ads Pre ApprovalTW | J29: =IFERROR(VLOOKUP(I29,'WFM Q4 Target'!J:K,2,0),"-") -> 256.044 | K29: 146.5343 | L29: 12.6506 | M29: =IFERROR(IF(K29>J29,"Not Meet Target","Meet Target"),"-") -> Meet Target | N29: =IFERROR(VLOOKUP(D29,'Team Member List'!B:C,2,0),"") -> TL Okafor | O29: View ticket
A30: First Review | C30: Freya Lindqvist | D30: Freya Lindqvist | E30: Bid Ads | F30: Bid Ad Group | G30: Bid Ad Group | H30: KH | I30: =TRIM(A30) & TRIM(F30) & TRIM(H30) -> First ReviewBid Ad GroupKH | J30: =IFERROR(VLOOKUP(I30,'WFM Q4 Target'!J:K,2,0),"-") -> 82.008 | K30: 419.6478 | L30: 105.018 | M30: =IFERROR(IF(K30>J30,"Not Meet Target","Meet Target"),"-") -> Not Meet Target | N30: =IFERROR(VLOOKUP(D30,'Team Member List'!B:C,2,0),"") -> TL Lindgren | O30: View ticket
A31: First Review | C31: Wei Chen | D31: Wei Chen | E31: Feature Ads | F31: Booking Ads Pre Approval | G31: Booking Ads Pre Approval | H31: TW | I31: =TRIM(A31) & TRIM(F31) & TRIM(H31) -> First ReviewBooking Ads Pre ApprovalTW | J31: =IFERROR(VLOOKUP(I31,'WFM Q4 Target'!J:K,2,0),"-") -> 256.044 | K31: 120.7444 | L31: 15.6377 | M31: =IFERROR(IF(K31>J31,"Not Meet Target","Meet Target"),"-") -> Meet Target | N31: =IFERROR(VLOOKUP(D31,'Team Member List'!B:C,2,0),"") -> TL Okafor | O31: View ticket
A32: First Review | C32: Sofia Novak | D32: Sofia Novak | E32: Feature Ads | F32: Highlight View | G32: Highlight View | H32: CZ | I32: =TRIM(A32) & TRIM(F32) & TRIM(H32) -> First ReviewHighlight ViewCZ | J32: =IFERROR(VLOOKUP(I32,'WFM Q4 Target'!J:K,2,0),"-") -> 6.51 | K32: 191.9052 | L32: 56.3737 | M32: =IFERROR(IF(K32>J32,"Not Meet Target","Meet Target"),"-") -> Not Meet Target | N32: =IFERROR(VLOOKUP(D32,'Team Member List'!B:C,2,0),"") -> TL Okafor | O32: View ticket
A33: First Review | D33: Sofia Novak | G33: Highlight View | H33: MX | I33: =TRIM(A33) & TRIM(F33) & TRIM(H33) -> First ReviewMX | J33: =IFERROR(VLOOKUP(I33,'WFM Q4 Target'!J:K,2,0),"-") -> - | K33: 269.1341 | L33: 0 | M33: =IFERROR(IF(K33>J33,"Not Meet Target","Meet Target"),"-") -> Meet Target | N33: =IFERROR(VLOOKUP(D33,'Team Member List'!B:C,2,0),"") -> TL Okafor | O33: View ticket
A34: First Review | D34: Sofia Novak | G34: Highlight View | H34: PH | I34: =TRIM(A34) & TRIM(F34) & TRIM(H34) -> First ReviewPH | J34: =IFERROR(VLOOKUP(I34,'WFM Q4 Target'!J:K,2,0),"-") -> - | K34: 174.5761 | L34: 0 | M34: =IFERROR(IF(K34>J34,"Not Meet Target","Meet Target"),"-") -> Meet Target | N34: =IFERROR(VLOOKUP(D34,'Team Member List'!B:C,2,0),"") -> TL Okafor | O34: View ticket
A35: First Review | C35: Andres Molina | D35: Andres Molina | E35: Feature Ads | F35: Booking Ads Pre Approval | G35: Booking Ads Pre Approval | H35: BR | I35: =TRIM(A35) & TRIM(F35) & TRIM(H35) -> First ReviewBooking Ads Pre ApprovalBR | J35: =IFERROR(VLOOKUP(I35,'WFM Q4 Target'!J:K,2,0),"-") -> 1137.432 | K35: 4592.4236 | L35: 29.4875 | M35: =IFERROR(IF(K35>J35,"Not Meet Target","Meet Target"),"-") -> Not Meet Target | N35: =IFERROR(VLOOKUP(D35,'Team Member List'!B:C,2,0),"") -> TL Cabrera | O35: View ticket
A36: First Review | C36: Dimitri Volkov | D36: Dimitri Volkov | E36: Bid Ads | F36: Bid Ad Group | G36: Bid Ad Group | H36: PH | I36: =TRIM(A36) & TRIM(F36) & TRIM(H36) -> First ReviewBid Ad GroupPH | J36: =IFERROR(VLOOKUP(I36,'WFM Q4 Target'!J:K,2,0),"-") -> 81.798 | K36: 209.2186 | L36: 41.3405 | M36: =IFERROR(IF(K36>J36,"Not Meet Target","Meet Target"),"-") -> Not Meet Target | N36: =IFERROR(VLOOKUP(D36,'Team Member List'!B:C,2,0),"") -> TL Okafor | O36: View ticket
A37: First Review | C37: Kenji Watanabe | D37: Kenji Watanabe | E37: Bid Ads | F37: Bid Ad Group | G37: Bid Ad Group | H37: AU | I37: =TRIM(A37) & TRIM(F37) & TRIM(H37) -> First ReviewBid Ad GroupAU | J37: =IFERROR(VLOOKUP(I37,'WFM Q4 Target'!J:K,2,0),"-") -> 88.71 | K37: 357.7315 | L37: 105.1676 | M37: =IFERROR(IF(K37>J37,"Not Meet Target","Meet Target"),"-") -> Not Meet Target | N37: =IFERROR(VLOOKUP(D37,'Team Member List'!B:C,2,0),"") -> TL Lindgren | O37: View ticket
